Traceback (most recent call last):
  File "/Users/moskowitzi/anaconda3/envs/astr330/lib/python3.9/site-packages/jupyter_cache/executors/utils.py", line 58, in single_nb_execution
    executenb(
  File "/Users/moskowitzi/anaconda3/envs/astr330/lib/python3.9/site-packages/nbclient/client.py", line 1305, in execute
    return NotebookClient(nb=nb, resources=resources, km=km, **kwargs).execute()
  File "/Users/moskowitzi/anaconda3/envs/astr330/lib/python3.9/site-packages/jupyter_core/utils/__init__.py", line 173, in wrapped
    return loop.run_until_complete(inner)
  File "/Users/moskowitzi/anaconda3/envs/astr330/lib/python3.9/asyncio/base_events.py", line 647, in run_until_complete
    return future.result()
  File "/Users/moskowitzi/anaconda3/envs/astr330/lib/python3.9/site-packages/nbclient/client.py", line 705, in async_execute
    await self.async_execute_cell(
  File "/Users/moskowitzi/anaconda3/envs/astr330/lib/python3.9/site-packages/nbclient/client.py", line 1058, in async_execute_cell
    await self._check_raise_for_error(cell, cell_index, exec_reply)
  File "/Users/moskowitzi/anaconda3/envs/astr330/lib/python3.9/site-packages/nbclient/client.py", line 914, in _check_raise_for_error
    raise CellExecutionError.from_cell_and_msg(cell, exec_reply_content)
nbclient.exceptions.CellExecutionError: An error occurred while executing the following cell:
------------------
# from dual_finder.preprocess_data.process_data import create_dataset
import importlib
import sys
#!pwd
sys.path.append("dual_finder/dual_finder/preprocess_data/")
#os.chdir("dual_finder/dual_finder/preprocess_data/")
sys.path.append("dual_finder/dual_finder/cnn/")
sys.path.append("dual_finder/dual_finder/visualize/")
sys.path.append("dual_finder/dual_finder/optimize/")
#os.chdir("/vast/palmer/scratch/urry/iam37/astr330")
#os.chdir("dual_finder/dual_finder/cnn/")

from process_data import create_dataset

from fits_utils import modified_plot_image as plot_image

from fits_utils import plot_dataset_sample

from create_cnn import ModelCreator

from load_model import loadModelClass

from train_cnn import DualFinder

from extract_feature_maps import FeatureExtractor

from optimize_hyperparameters import OptimizeHyperparameters
from visualize_performance import load_training_history, plot_training_progress, plot_grouped_training_progress, VisualizeOptimization

%load_ext autoreload
%reload_ext autoreload
%autoreload 2
#os.chdir("/vast/palmer/scratch/urry/iam37/astr330")
------------------


[0;31m---------------------------------------------------------------------------[0m
[0;31mModuleNotFoundError[0m                       Traceback (most recent call last)
Cell [0;32mIn[2], line 13[0m
[1;32m      9[0m sys[38;5;241m.[39mpath[38;5;241m.[39mappend([38;5;124m"[39m[38;5;124mdual_finder/dual_finder/optimize/[39m[38;5;124m"[39m)
[1;32m     10[0m [38;5;66;03m#os.chdir("/vast/palmer/scratch/urry/iam37/astr330")[39;00m
[1;32m     11[0m [38;5;66;03m#os.chdir("dual_finder/dual_finder/cnn/")[39;00m
[0;32m---> 13[0m [38;5;28;01mfrom[39;00m [38;5;21;01mprocess_data[39;00m [38;5;28;01mimport[39;00m create_dataset
[1;32m     15[0m [38;5;28;01mfrom[39;00m [38;5;21;01mfits_utils[39;00m [38;5;28;01mimport[39;00m modified_plot_image [38;5;28;01mas[39;00m plot_image
[1;32m     17[0m [38;5;28;01mfrom[39;00m [38;5;21;01mfits_utils[39;00m [38;5;28;01mimport[39;00m plot_dataset_sample

[0;31mModuleNotFoundError[0m: No module named 'process_data'

